<?xml version="1.0"?>
<robot xmlns:xacro="http://www.ros.org/wiki/xacro">

  <!--                                                                      -->
  <!-- MACRO FOR THRUSTER UNITS  -->
  <!--                                                                      -->

  <!-- Provide the propeller mesh in a separate file with the rotation axis
  over propeller's frame X-axis in DAE (Collada) or STL format.
  -->
  <!-- <xacro:property name="prop_mesh_file" value="file://$(find core)/descriptions/alfie_description/meshes/propeller.dae"/> -->

  <!--
    Thruster macro with integration of joint and link. The thrusters should
    be initialized in the actuators.xacro file.
  -->
  <xacro:macro name="thruster_macro" params="robot_namespace thruster_id *origin">

    <!--
    Dummy link as place holder for the thruster frame,
    since thrusters can often be inside the collision geometry
    of the vehicle and may cause internal collisions if set otherwise
    -->
    <link name="${robot_namespace}/thruster_${thruster_id}">

      <!-- <visual>
        <geometry>
          <mesh filename="${prop_mesh_file}" scale="1 1 1" />
        </geometry>
      </visual> -->

      <inertial>
        <mass value="0.001" />
        <origin xyz="0 0 0" rpy="0 0 0"/>
        <inertia ixx="0.000000017" ixy="0.0" ixz="0.0"
               iyy="0.000000017" iyz="0.0"
               izz="0.000000017" />
      </inertial>
    </link>

    <!-- Joint between thruster link and vehicle base link -->
    <joint name="${robot_namespace}/thruster_${thruster_id}_joint" type="continuous">
      <xacro:insert_block name="origin" />
      <axis xyz="1 0 0" />
      <parent link="${robot_namespace}/base_link" />
      <child link="${robot_namespace}/thruster_${thruster_id}" />
    </joint>

    <gazebo>
      <!-- Thruster ROS plugin -->
      <plugin name="${robot_namespace}_${thruster_id}_thruster_model" filename="libuuv_thruster_ros_plugin.so">
        <!-- Name of the thruster link -->
        <linkName>${robot_namespace}/thruster_${thruster_id}</linkName>

        <!-- Name of the joint between thruster and vehicle base link -->
        <jointName>${robot_namespace}/thruster_${thruster_id}_joint</jointName>

        <!-- Make the thruster aware of its id -->
        <thrusterID>${thruster_id}</thrusterID>

        <!-- Gain of the input command signal -->
        <gain>1</gain>

        <!-- Maximum allowed input value for the input signal for thruster unit -->
        <clampMax>0</clampMax>

        <!-- Minimum allowed value for the input signal for thruster unit -->
        <clampMin>0</clampMin>

        <!-- Minimum and maximum thrust force output allowed -->
        <thrustMin>0</thrustMin>
        <thrustMax>0</thrustMax>

        <!--
        Value from 0 to 1 to set the efficiency of the output thrust force
        Default value is 1.0
        -->
        <thrust_efficiency>1</thrust_efficiency>

        <!--
        Value from 0 to 1 to set the efficiency of the propeller as a factor
        to be multiplied to the current value of the state variable at each
        iteration.
        Default value is 1.0
        -->
        <propeller_efficiency>1</propeller_efficiency>

        <!--
        Choose one of the propeller dynamics models below for your implementation
        This will describe the dynamic model for the state variable of your thruster unit,
        which can be, e.g., the angular velocity of the propeller.
        -->

        <!-- 1) Simple zero-order model -->
        <dynamics>
          <type>ZeroOrder</type>
        </dynamics>

        <!--
        Choose one of the model for the steady-state curve describing the
        relationship between the state variable and the output thrust force
        -->

        <!-- 1) Basic curve
        Input: x
        Output: thrust
        Function: thrust = rotorConstant * x * abs(x)
        -->
        <conversion>
          <type>Basic</type>
          <rotorConstant>1</rotorConstant>
        </conversion>

        <!-- 2) Dead-zone nonlinearity described in Bessa, 2006
        Input: x
        Output: thrust
        Function:
        thrust = rotorConstantL * (x * abs(x) - deltaL), if x * abs(x) <= deltaL
        thrust = 0, if deltaL < x * abs(x) < deltaR
        thrust = rotorConstantR * (x * abs(x) - deltaR), if x * abs(x) >= deltaL

        <conversion>
          <type>Bessa</type>
          <rotorConstantL>0.0</rotorConstantL>
          <rotorConstantR>0.0</rotorConstantR>
          <deltaL>0.0</deltaL>
          <deltaR>0.0</deltaR>
        </conversion>

        3) Linear interpolation
        If you have access to the thruster's data sheet, for example,
        you can enter samples of the curve's input and output values
        and the thruster output will be found through linear interpolation
        of the given samples.

        <conversion>
          <type>LinearInterp</type>
          <inputValues>0 1 2 3</inputValues>
          <outputValues>0 1 2 3</outputValues>
        </conversion>
      -->

      </plugin>
    </gazebo>

    <gazebo reference="${robot_namespace}/thruster_${thruster_id}">
      <selfCollide>false</selfCollide>
    </gazebo>
  </xacro:macro>


  <!--                                                                      -->
  <!-- MACRO FOR FIN/RUDDER UNITS  -->
  <!--                                                                      -->

  <!--
    This macro can be used to add fins to the body of the vehicle, the fins
    should be initialized in the actuators.xacro file. If you vehicle has no
    fins, you can erase the macro below.
  -->

  <!-- A separate mesh for the fin should be stored in the meshes folder -->
  <!-- <xacro:property name="fin_mesh_file" value="file://$(find core)/descriptions/alfie_description/meshes/fin.dae"/>
-->
  <!-- Fin joint limits
  <xacro:property name="fin_min_joint_limit" value="${0.0 * d2r}"/>
  <xacro:property name="fin_max_joint_limit" value="${0.0 * d2r}"/>

  <xacro:macro name="fin_macro" params="namespace fin_id *origin">
      <joint name="${namespace}/fin${fin_id}_joint" type="revolute">
          <limit effort="0" lower="${fin_min_joint_limit}" upper="${fin_max_joint_limit}" velocity="0"/>
          <xacro:insert_block name="origin"/>
          <axis xyz="0 0 1"/>
          <parent link="${namespace}/base_link" />
          <child link="${namespace}/fin${fin_id}" />
      </joint>

      <link name="${namespace}/fin${fin_id}">
        <inertial>
          <mass value="0.001" />
          <origin xyz="0 0 0" rpy="0 0 0"/>
          <inertia ixx="0.000000017" ixy="0.0" ixz="0.0"
                 iyy="0.000000017" iyz="0.0"
                 izz="0.000000017" />
        </inertial>
        <visual>
          <origin xyz="0 0 0" rpy="0 0 0" />
          <geometry>
            <mesh filename="${fin_mesh_file}" scale="1 1 1"/>
          </geometry>
        </visual>
      </link>

      <gazebo>
        <plugin name="${namespace}_fin${fin_id}_model" filename="libuuv_fin_ros_plugin.so">


            First order dynamics model for the fin joint dynamics,
            replace an appropriate time constant

          <dynamics>
            <type>FirstOrder</type>
            <timeConstant>0.0</timeConstant>
          </dynamics>


            Definition of the lift and drag model, choose ONE of the models
            below according to the model you want to use.



            2) Reference for the quadratic lift and drag model:
              [1] Engelhardtsen, Oystein. 3D AUV Collision Avoidance.
                  MS thesis. Institutt for teknisk kybernetikk, 2007.
                  https://brage.bibsys.no/xmlui/handle/11250/259834
          <liftdrag>
            <type>Quadratic</type>
            <lift_constant>0.0</lift_constant>
            <drag_constant>0.0</drag_constant>
          </liftdrag>

            Further parameters necessary for the lift and drag plugin

          <current_velocity_topic>/hydrodynamics/current_velocity</current_velocity_topic>

          <link_name>${namespace}/fin${fin_id}</link_name>
          <joint_name>${namespace}/fin${fin_id}_joint</joint_name>

          <output_topic>${namespace}/fins/${fin_id}/output</output_topic>
          <input_topic>${namespace}/fins/${fin_id}/input</input_topic>
          <wrench_topic>${namespace}/fins/${fin_id}/wrench_topic</wrench_topic>
        </plugin>
      </gazebo>
  </xacro:macro> -->

</robot>
